Workbook

Sheet Customers
A1: CustomerName | B1: CustomerCode | C1: Address | D1: ContactPerson | E1: Phone | F1: Email | G1: Production_2025 | H1: Production_2026 | I1: In_Production | J1: Level | K1: Update_date
A2: PL | B2: Polypack | C2: Korea | D2: Hong | E2: 010-xxxx-xxxx | F2: polypack11115@gmail.com | G2: 1400000 | H2: 100000 | I2: 80000 | J2: A | K2: 46081
A6: Màn hình Customers
A20: Khi click vào thêm khách mới hiển thị form nhập liệu

Sheet Products
A1: CustomerCode | B1: Productname | C1: Productcode | D1: S.W.L | E1: Type | F1: Sewing | G1: SpecOther | H1: SpecInner | I1: Color | J1: Liner | K1: Print | L1: Top | M1: Bottom | N1: Packing | O1: Other | P1: Update_date
A2: FL | B2: Lotte Starex 600kg | C2: LAM001 | D2: 600kg | E2: Rope | F2: Inside | G2: 96*96*129 | H2: 93*93*118 | I2: BG | J2: 0.05*190*280 | K2: Có | L2: 40*55 | M2: 40*40 | N2: 100 | O2: Chú ý vị trí pocket | P2: =today() -> 46082
D34: Thắc mắc | E34: kiểu chọn | F34: kiểu nhập | G34: Tự động điền có tính năng sửa
A37: 1. Products | B37: 1
A38: CustomerCode | B38: Productname | C38: Productcode | D38: S.W.L | E38: Type | F38: Sewing | G38: SpecOther | H38: SpecInner | I38: Color | J38: Liner | K38: Print | L38: Top | M38: Bottom | N38: Packing | O38: Other | P38: Update_date
A39: 1 | B39: 2 | C39: 3 | D39: 4 | E39: 5 | F39: 6 | G39: 7 | H39: 8 | I39: 9 | J39: 10 | K39: 11 | L39: 12 | M39: 13 | N39: 14 | O39: 15 | P39: 16
H40: aaa*bbb*ccc | L40: aa*bb
A41: FL | B41: Lotte Starex 600kg | C41: LAM001 | D41: 600kg | E41: Belt Rope | G41: 96*96*129 | H41: 93*93*118 | I41: BG | J41: 0.05*190*280 | K41: Có | L41: 40*55 | M41: 40*40 | N41: 100 | O41: Chú ý vị trí pocket | P41: =today() -> 46082
A42: 2.Products_S
A43: ProductCode | B43: Item | C43: MaterialGroup | D43: Spec | E43: Item_Size | F43: Lami | G43: Item_Color | H43: Unit Weight(kg) | I43: Q'ty(m or m2) | J43: PCS (EA) | K43: WT (kg) | L43: Other | M43: << tham khảo bảng bên dưới
A44: 1 | B44: 2 | C44: 3 | D44: 4 | E44: 5 | F44: 6 | G44: 7 | H44: 8 | I44: 9 | J44: 10 | K44: 11 | L44: 12
A45: =Products!C45 -> Vải | B45: Vải thân dài | C45: Vải | D45: 1350D*14*14 | E45: 99*130 | F45: Không | G45: BG | H45: {=XLOOKUP(D45,Unit_W!A:A,Unit_W!B:B, "")} -> #REF! | I45: =E45*#REF!/10000 -> #REF! | J45: 1 | K45: =I45*H45 -> #REF!
A48: 1.5 | B48: 1.6 | C48: 1.11 | E48: 2.2 | G48: 2.3
A49: Type | B49: Sewing | C49: Print | E49: Item | F49: Spec | G49: Item_size | I49: Ví dụ | J49: Item_color | K49: Ví dụ BG | L49: Mater | M49: 1 | N49: 2 | P49: 4 | Q49: 5 | R49: 6 | S49: 7 | T49: 8 | U49: 9
A50: Belt Upanel | B50: OutSide | C50: Yes | E50: Thân dài | F50: Nhập 1 lần đầu tự cập nhật các item còn lại tuy nhiên để trạng thái có thể sửa | G50: =(1.8a+8)*(1.8c+1.8b+1.8c+10) | I50: 101*339 | J50: =1.9 | K50: BG | L50: PP Cloth | M50: Spec | N50: Item_Size | O50: Lami | P50: Item_Color | Q50: Unit Weight(kg) | R50: Q'ty(m or m2) | S50: PCS (EA) | T50: WT (kg) | U50: Other
A51: Rope Upanel | B51: InSide | C51: No | E51: Thân ngắn | G51: =(1.8a+8)*(1.8c+9) | I51: 101*127 | J51: =1.9 | K51: BG | L51: Tarpaulin | M51: Spec | N51: Item_Size | O51: Lami | P51: Item_Color | Q51: Unit Weight(kg) | R51: Q'ty(m or m2) | S51: PCS (EA) | T51: WT (kg) | U51: Other
A52: Belt Tubular | B52: Other ( nhập ) | E52: Thân ống | G52: =((1.8a+1.8b)*2)*((1.8c+8)) | I52: 372*126 | J52: =1.9 | K52: BG | L52: PE Liner | M52: Spec | Q52: Unit Weight(kg) | T52: WT (kg) | U52: Other
A53: Rope Tubular | E53: Thân trước sau | G53: =G51 -> =(1.8a+8)*(1.8c+9) | I53: 101*127 | J53: =1.9 | K53: BG | L53: PP Rope | M53: Spec | N53: Item_Size | P53: Item_Color | Q53: Unit Weight(kg) | R53: Q'ty(m or m2) | T53: WT (kg) | U53: Other
A54: 4 Panel | E54: Thân mặt cạnh | G54: =(1.8b+8)*(1.8c+9) | I54: 101*127 | J54: =1.9 | K54: BG | L54: PP Tape | M54: Spec | N54: Item_Size | P54: Item_Color | Q54: Unit Weight(kg) | R54: Q'ty(m or m2) | T54: WT (kg) | U54: Other
A55: Belt Circular | E55: Thân quây | G55: =((1.8a+1.8b)*2+8)*(1.8c+9) | I55: 380*127 | J55: =1.9 | K55: BG | L55: Thread | M55: Spec | T55: WT (kg) | U55: Other
A56: Rope Circular | E56: Miệng xả tròn | G56: =(1.8a+8)*(1.8b+8) | I56: 101*101 | J56: =1.9 | K56: BG | L56: Slider | M56: Spec | N56: Item_Size | Q56: Unit Weight(kg) | R56: Q'ty(m or m2) | T56: WT (kg) | U56: Other
A57: Bao cuốn | E57: Đáy xả tròn | G57: '=(1.8a+8)*(1.8b+8) | I57: 101*101 | J57: =1.9 | K57: BG | L57: Label | M57: Spec | Q57: Unit Weight(kg) | T57: WT (kg) | U57: Other
A58: Other( nhập) | E58: Miệng xả chéo | G58: '=(1.8a+8)*(1.8b+8) | I58: 101*101 | J58: =1.9 | K58: BG | L58: Vải lưới | M58: Spec | N58: Item_Size | P58: Item_Color | Q58: Unit Weight(kg) | R58: Q'ty(m or m2) | T58: WT (kg) | U58: Other
E59: Đáy xả chéo | G59: '=(1.8a+8)*(1.8b+8) | I59: 101*101 | J59: =1.9 | K59: BG
E60: Bocang | G60: nhập dạng aa*bb | I60: 10*10 | J60: =1.9 | K60: BG
E61: Đáp đai | G61: nhập dạng aa*bb | I61: 10*11 | J61: =1.9 | K61: BG
E62: Tucong M | G62: nhập dạng aa*bb | I62: 10*12 | J62: =1.9 | K62: BG
E63: Tucong Đ | G63: nhập dạng aa*bb | I63: 10*13 | J63: =1.9 | K63: BG
E64: TCM | F64: Nhập 1 lần đầu tự cập nhật các item còn lại tuy nhiên để trạng thái có thể sửa | G64: =(1.12a*3.14+8)*(1.12b+5) | I64: 134*60 | J64: Nhập ( để mặc định là WT )
E65: TCĐ | G65: =(1.13a*3.14+8)*(1.13b+5) | I65: 134*45 | J65: Nhập ( để mặc định là WT ) | L65: Bảng Unit Weigt(kg)
E66: Tapchi | G66: Nhập dạng aa*bb | I66: 10*10 | J66: Nhập ( để mặc định là WT ) | L66: PP Cloth | M66: Ví dụ : Spec vải 1350D*14*14 | O66: UW= 1350*(14+14)*0.091*0.05/1000 | R66: =1350*(14+14)*0.091*0.05/1000 -> 0.17199 | S66: Nếu Lami có thì + 0.025 | U66: =R66+0.025 -> 0.19699
E67: Tấm chống bẩn | G67: Nhập dạng aa*bb | I67: 10*11 | J67: Nhập ( để mặc định là WT ) | L67: Tarpaulin | M67: Spec vải có dạng " PE aD*b*c " | O67: UW= a*(b+c)*0.091*0.06/1000 | Q67: PE 800D*8*8 | R67: 0.06988 | S67: Không phụ thuộc vào lami
E68: POCKET | F68: Nhập text | G68: Nhập dạng aa*bb | I68: 10*12 | J68: Nhập ( để mặc định là WT ) | L68: PE Liner | M68: Spec có dạng a*b*c | O68: UW=a*b*c*2*926/10000000 | R68: =0.05*190*280*2*926/10000000 -> 0.492632
E69: LINER | G69: =1.10 | I69: =J41 -> 0.05*190*280 | L69: PP Rope | M69: Bảng chọn có sẵn định lượng
B70: C | E70: Chạc M | F70: Chọn | G70: Nhập dạng aaa | I70: 180 | J70: Nhập ( để mặc định là WT ) | L70: PP Tape | M70: Mặc định = 0.006
E71: Chạc Đ | F71: Chọn | G71: Nhập dạng aaa | I71: 100 | J71: Nhập ( để mặc định là WT ) | L71: Slider | M71: Bảng chọn có sẵn định lượng
E72: Tape M | F72: Chọn | G72: Nhập dạng aaa | I72: 100 | J72: Nhập ( để mặc định là BG) | L72: Label | M72: 0
E73: Tape Đ | F73: Chọn | G73: Nhập dạng aaa | I73: 100 | J73: Nhập ( để mặc định là BG) | L73: Vải lưới | M73: Nhập
E74: Chạc | F74: Chọn | G74: Nhập dạng aaa | I74: 100 | J74: Nhập ( để mặc định là WT )
E75: Chạc nâng | F75: Chọn | G75: Nhập dạng aaa | I75: 100 | J75: Nhập ( để mặc định là WT ) | L75: Bảng Q'ty(m or m2)
...

Sheet Form_Specification
A1: Bảng chi tiết spec sản phẩm
A2: Tên sản phẩm (productname) | C2: =Products!B2 -> Lotte Starex 600kg | D2: Mã khách hàng | F2: FL
A3: Kích thước sử dụng(spec inner) | C3: =Products!H2 -> 93*93*118 | D3: Bản cập nhật | F3: =Products!P2 -> 46082 | I3: data lấy từ Products
A4: Quy cách Tapchi (product _top/bottom) | D4: =Products!L2 -> 40*55 | E4: Đáy | F4: =Products!M2 -> 40*40
A6: STT | B6: Tên phụ kiện (Item) | C6: Quy cách ( Spec) | D6: Màu ( Color) | E6: Coating (:Lami) | F6: Kích thước cắt(cm)(Item_Size) | G6: Định lượng ( Unit Weight) | H6: Q'ty (m/m2) | I6: Tổng trọng lượng ( Total Weight) | J6: Note
A22: Tổng | I22: =sum(I7:I21) -> 0
I23: MINH PHUONG GROUP CO., LTD

Sheet Form_Product
A1: Bảng thông tin sản phẩm - LT Starex 600kg
A2: Tên sản phẩm | C2: Mã sản phẩm | E2: Bản in 1 | H2: Bản in 2
A3: Mã khách hàng | C3: Ngày cập nhật
A4: S.W.L | C4: Type
A5: Sewing | C5: Color
A6: SpecOther | C6: SpecInner
A7: Liner | C7: Label
A8: Top | C8: Bottom
A9: Packing
A10: Chọn item trong products_S để show thêm theo yêu cầu
A11: ... | C11: ...
A18: ... | C18: ...
A20: Other :
I23: MINH PHUONG GROUP CO., LTD

Sheet Item
A1: Item | B1: Belt Upanel | C1: Rope Upanel | D1: Belt Tubular | E1: Rope Tubular | F1: 4 Panel | G1: Belt Circular | H1: Rope Circular | I1: Bao cuốn | J1: Size | K1: MaterialGroup
A2: Thân dài | B2: O | C2: O | J2: 1*1*1 | K2: PP Cloth | L2: 1350D*14*14 | M2: Item_Size | N2: Lami | O2: Item_Color | P2: Unit Weight(kg) | Q2: Q'ty(m or m2) | R2: PCS (EA) | S2: WT (kg) | T2: Other
A3: Thân ngắn | B3: O | C3: O | K3: Tarpaulin | L3: Spec | M3: Item_Size | N3: Lami | O3: Item_Color | P3: Unit Weight(kg) | Q3: Q'ty(m or m2) | R3: PCS (EA) | S3: WT (kg) | T3: Other
A4: Thân ống | D4: O | E4: O | G4: O | H4: O | K4: PE Liner | L4: Spec | P4: Unit Weight(kg) | R4: PCS (EA) | S4: WT (kg) | T4: Other
A5: Thân trước sau | F5: O | K5: PP Rope | L5: Spec | O5: Item_Color | P5: Unit Weight(kg) | Q5: Q'ty(m or m2) | R5: PCS (EA) | S5: WT (kg) | T5: Other
A6: Thân mặt cạnh | F6: O | K6: PP Tape | L6: Spec | O6: Item_Color | P6: Unit Weight(kg) | Q6: Q'ty(m or m2) | R6: PCS (EA) | S6: WT (kg) | T6: Other
A7: Thân quây | I7: O | K7: Thread | L7: Spec | R7: PCS (EA) | S7: WT (kg) | T7: Other
A8: Miệng xả tròn | K8: Slider | L8: Spec | P8: Unit Weight(kg) | Q8: Q'ty(m or m2) | R8: PCS (EA) | S8: WT (kg) | T8: Other
A9: Đáy xả tròn | K9: Label | L9: Spec | P9: Unit Weight(kg) | R9: PCS (EA) | S9: WT (kg) | T9: Other
A10: Miệng xả chéo | K10: Vải lưới | L10: Spec | O10: Item_Color | P10: Unit Weight(kg) | Q10: Q'ty(m or m2) | R10: PCS (EA) | S10: WT (kg) | T10: Other
A11: Đáy xả chéo
A12: Bocang | B12: O | C12: O
A13: Đáp đai
A14: Tucong M
A15: Tucong Đ
A16: TCM
A17: TCĐ
A18: Tapchi
A19: Tấm chống bẩn
A20: POCKET
A21: LINER
A22: Chạc M
A23: Chạc Đ
A24: Tape M
... A26: Chạc
A27: Chạc nâng | C27: O | E27: O | H27: O
A28: Đai nâng | B28: O | D28: O | G28: O
A29: Đai bo thân
A30: Đai bo miệng
A31: Đai bo đáy
A32: Đai ngang
A33: Đai
A34: Tấm chống phình
A35: Mếch
A36: Dây chống xì
A37: Nhám
A38: P.V.C
A39: Chỉ may | B39: O | C39: O | D39: O | E39: O | F39: O | G39: O | H39: O | I39: O
A40: Label

Sheet Products_S
A1: ProductCode | B1: Item | C1: MaterialGroup | D1: Spec | E1: Item_Size | F1: Lami | G1: Item_Color | H1: Unit Weight(kg) | I1: Q'ty(m or m2) | J1: PCS (EA) | K1: WT (kg) | L1: Other
A2: =Products!C2 -> LAM001 | B2: Vải thân dài | C2: Vải | D2: 1350D*14*14 | E2: 99*130 | F2: Không | G2: BG | H2: {=XLOOKUP(D2,Unit_W!A:A,Unit_W!B:B, "")} -> #REF! | I2: =E2*#REF!/10000 -> #REF! | J2: 1 | K2: =I2*H2 -> #REF!
A3: =Products!C3
A4: =Products!C4
A5: =Products!C5
A6: =Products!C6
A7: =Products!C7
A8: =Products!C8
M9: Thêm nút sửa
A72: 작성자 : ㈜ 폴리팩 | B72: 백중량 : kg | N72: 20년 01월 28일
A73: 대성광보 무인쇄 | E73: 대 성 광보 | G73: Bulkconbag 생산의뢰서 | K73: 단위:cm | L73: 인 쇄 사 양
E74: 작성일자 | F74: 20년01월28일 | H74: 소 요 자 재 | J74: 자 재 규 격 | K74: 비 고 | L74: 색상 | M74: 군청색 | N74: 색도 | O74: 1도/1면
E75: 생의번호 | G75: 1 | H75: 대 판 | I75: PP | J75: 1300D 13x12x180 베이지 | K75: beige | L75: 앞 면 인 쇄
E76: 베트남C/N | K76: beige | L76: 없 음
E77: 수 량 | G77: 2 | H77: 하 판 | I77: PP | J77: 1300D 13x12x98 베이지 | K77: beige
E78: 규 격 | F78: 90*90*140 | G78: 3 | H78: 상 판 | I78: PP | J78: 1300D 13x12x98 베이지 | K78: beige
E79: 내 용 물 | G79: 4 | H79: 상부크로스마감 | I79: PP | J79: 1300D 13x12x98 베이지 | K79: beige
E80: 주 입 구 | F80: Φ45 x 55 | G80: 5 | H80: 하부크로스마감 | I80: PP | J80: 1300D 13x12x98 베이지 | K80: beige
E81: 배 출 구 | F81: Φ45 x 55 | G81: 6 | H81: 주 입 구 | I81: PE | J81: 850D 8x8/SQ.INCH N/WHITE | K81: IN-Lami
E82: S. W. L | F82: 500kg | G82: 7 | H82: 배 출 구 | I82: PE | J82: 850D 8x8/SQ.INCH N/WHITE | K82: 〃
E83: 출 고 일 | G83: 8 | H83: ROPE 리프트 | I83: PP | J83: 12 mm WIDTH WHITE ,4.8 M | K83: WHITE
E84: 도 착 지 | G84: 9 | H84: 라운드벨트
E85: 포 장 | F85: 100pcs | G85: 10 | H85: 링벨트(고리)
E86: P . E | F86: 0.05*185*330 | G86: 11 | H86: 고리로프
E87: LINER | G87: 12 | H87: 주입구테이프 | I87: PP | J87: 20 mm / 1M | K87: WHITE | L87: 뒷 면 인 쇄
G88: 13 | H88: 배출구테이프 | I88: PP | J88: 20 mm / 1M | K88: WHITE | L88: 없 음
E89: (선적마크) | G89: 14 | H89: 보 강 대 | I89: PP | J89: 1300D 13x12/SQ.INCH LAMI | K89: BEIGE
E90: 품명 | G90: 15 | H90: 주입구 로프 | I90: PP | J90: 5 mm DIA ROPE WHITE | K90: 1.7M
E91: 수량 | F91: 100PCS | G91: 16 | H91: 배출구 로프 | I91: PP | J91: 5 mm DIA ROPE WHITE | K91: 1.7M
E92: 제조일 | F92: 200 . . | G92: 17 | H92: 보 호 로 프
D93: ` | E93: 제조업체 | G93: 18 | H93: P E 호스 | J93: 13 mm DIA HOSE WHITE | K93: 3cm
G94: 19 | H94: 뚜 껑 | I94: PP | J94: 1300D 13X12/ 베이지 | K94: 30X30
E95: 결 | G95: 20 | H95: POCKET | I95: PE | J95: 20*25 (내경기준) | K95: 1EA
G96: 21 | H96: 라 벨 | J96: vietnam + 분리배출마크 | K96: 1EA
E97: 재 | G97: 22 | H97: 봉 사 실 | J97: 1000D/2합
G98: 23 | H98: 오염방지천 | J98: 없 음

Sheet Production_Plan
A1: CustomerCode | B1: LOT | C1: ETD | D1: ETA | E1: ContP_Date | F1: Productcode | G1: OrderQ'ty (PCS) | H1: SpecInner | I1: Liner | J1: Print | K1: Label | L1: SewingType | M1: Packing | N1: Status | O1: Update_date | P1: Update_person

Sheet Print_URL
A1: Productcode | B1: Version | C1: Print_1 | D1: Print_2 | E1: Print_3 | F1: Print_4 | G1: CreatAt
